Workbook

Sheet Dashboard
B1: AI Operating System
B2: ="As of "&TEXT(AsOf,"ddd d mmm yyyy")&IF(OwnerName="",""," · "&OwnerName) -> As of Mon 5 Oct 2026 | F2: =IF(SampleAsOf<>"","SAMPLE DATA. Open AI-OS.xlsx for the blank workbook.",IF(SnapshotAt="","No Jira snapshot yet. Say: refresh dashboard",IF(SnapshotAge>SnapshotMaxAge,"Jira snapshot is "&SnapshotAge&" days old. Say: refresh dashboard","Jira snapshot "&TEXT(SnapshotAt,"d mmm hh:mm")&" from "&SnapshotSource))) -> No Jira snapshot yet. Say: refresh dashboard
C4: OPEN DECISIONS | F4: UNCONFIRMED | G4: OPEN CONFLICTS | J4: JIRA NEEDING ATTENTION | K4: DONE THIS WEEK
C5: =COUNTIFS(Inventory!$K:$K,"Open",Inventory!$C:$C,"Decision") -> 0 | F5: =COUNTIF(Inventory!$K:$K,"Unconfirmed") -> 0 | G5: =COUNTIFS(Inventory!$K:$K,"Open",Inventory!$C:$C,"Conflict") -> 0 | J5: =COUNTIF(Jira!$P:$P,"Critical")+COUNTIF(Jira!$P:$P,"Warning") -> 0 | K5: =COUNTIF(Done!$G:$G,"Yes") -> 0
C6: =COUNTIFS(Inventory!$K:$K,"Open",Inventory!$C:$C,"Decision",Inventory!$M:$M,"Critical")&" past "&DecisionCritical&" days" -> 0 past 7 days | F6: =COUNTIFS(Inventory!$K:$K,"Unconfirmed",Inventory!$M:$M,"Warning")&" older than "&UnconfirmedWarn&" days" -> 0 older than 5 days | G6: ="inventory stands until settled" -> inventory stands until settled | J6: ="of "&(COUNTA(Jira!$A$2:$A$501)-COUNTIF(Jira!$P:$P,"Closed"))&" in flight · "&COUNTIF(Jira!$P:$P,"Critical")&" critical" -> of 0 in flight · 0 critical | K6: =COUNTIF(Done!$F:$F,AsOf-WEEKDAY(AsOf,3)-7)&" last week · "&COUNTIF(Answers!$D:$D,"Reuse")&" answers reused" -> 0 last week · 0 answers reused
B8: Needs you | E8: Open decisions, conflicts and unconfirmed items, worst first. Paste the last column into Cowork.
B9: # | C9: ID | D9: Type | E9: Topic | F9: Summary | G9: Age (d) | H9: Severity | I9: From | J9: Say this
B10: 1 | C10: =IFERROR(INDEX(Inventory!$A$2:$A$1001,MATCH(LARGE(Inventory!$N$2:$N$1001,$B10),Inventory!$N$2:$N$1001,0)),"") | D10: =IF($C10="","",INDEX(Inventory!$C$2:$C$1001,MATCH($C10,Inventory!$A$2:$A$1001,0))&"") | E10: =IF($C10="","",INDEX(Inventory!$D$2:$D$1001,MATCH($C10,Inventory!$A$2:$A$1001,0))&"") | F10: =IF($C10="","",INDEX(Inventory!$E$2:$E$1001,MATCH($C10,Inventory!$A$2:$A$1001,0))&"") | G10: =IF($C10="","",INDEX(Inventory!$L$2:$L$1001,MATCH($C10,Inventory!$A$2:$A$1001,0))) | H10: =IF($C10="","",INDEX(Inventory!$M$2:$M$1001,MATCH($C10,Inventory!$A$2:$A$1001,0))&"") | I10: =IF($C10="","",INDEX(Inventory!$F$2:$F$1001,MATCH($C10,Inventory!$A$2:$A$1001,0))&"") | J10: =IF($C10="","",INDEX(Inventory!$O$2:$O$1001,MATCH($C10,Inventory!$A$2:$A$1001,0))&"") | K10: =IF(COUNT(Inventory!$N$2:$N$1001)=0,"Nothing open. Inventory is clear.",IF(COUNT(Inventory!$N$2:$N$1001)>10,"+"&(COUNT(Inventory!$N$2:$N$1001)-10)&" more on the Inventory sheet","")) -> Nothing open. Inventory is clear.
B11: 2 | C11: =IFERROR(INDEX(Inventory!$A$2:$A$1001,MATCH(LARGE(Inventory!$N$2:$N$1001,$B11),Inventory!$N$2:$N$1001,0)),"") | D11: =IF($C11="","",INDEX(Inventory!$C$2:$C$1001,MATCH($C11,Inventory!$A$2:$A$1001,0))&"") | E11: =IF($C11="","",INDEX(Inventory!$D$2:$D$1001,MATCH($C11,Inventory!$A$2:$A$1001,0))&"") | F11: =IF($C11="","",INDEX(Inventory!$E$2:$E$1001,MATCH($C11,Inventory!$A$2:$A$1001,0))&"") | G11: =IF($C11="","",INDEX(Inventory!$L$2:$L$1001,MATCH($C11,Inventory!$A$2:$A$1001,0))) | H11: =IF($C11="","",INDEX(Inventory!$M$2:$M$1001,MATCH($C11,Inventory!$A$2:$A$1001,0))&"") | I11: =IF($C11="","",INDEX(Inventory!$F$2:$F$1001,MATCH($C11,Inventory!$A$2:$A$1001,0))&"") | J11: =IF($C11="","",INDEX(Inventory!$O$2:$O$1001,MATCH($C11,Inventory!$A$2:$A$1001,0))&"")
B12: 3 | C12: =IFERROR(INDEX(Inventory!$A$2:$A$1001,MATCH(LARGE(Inventory!$N$2:$N$1001,$B12),Inventory!$N$2:$N$1001,0)),"") | D12: =IF($C12="","",INDEX(Inventory!$C$2:$C$1001,MATCH($C12,Inventory!$A$2:$A$1001,0))&"") | E12: =IF($C12="","",INDEX(Inventory!$D$2:$D$1001,MATCH($C12,Inventory!$A$2:$A$1001,0))&"") | F12: =IF($C12="","",INDEX(Inventory!$E$2:$E$1001,MATCH($C12,Inventory!$A$2:$A$1001,0))&"") | G12: =IF($C12="","",INDEX(Inventory!$L$2:$L$1001,MATCH($C12,Inventory!$A$2:$A$1001,0))) | H12: =IF($C12="","",INDEX(Inventory!$M$2:$M$1001,MATCH($C12,Inventory!$A$2:$A$1001,0))&"") | I12: =IF($C12="","",INDEX(Inventory!$F$2:$F$1001,MATCH($C12,Inventory!$A$2:$A$1001,0))&"") | J12: =IF($C12="","",INDEX(Inventory!$O$2:$O$1001,MATCH($C12,Inventory!$A$2:$A$1001,0))&"")
B13: 4 | C13: =IFERROR(INDEX(Inventory!$A$2:$A$1001,MATCH(LARGE(Inventory!$N$2:$N$1001,$B13),Inventory!$N$2:$N$1001,0)),"") | D13: =IF($C13="","",INDEX(Inventory!$C$2:$C$1001,MATCH($C13,Inventory!$A$2:$A$1001,0))&"") | E13: =IF($C13="","",INDEX(Inventory!$D$2:$D$1001,MATCH($C13,Inventory!$A$2:$A$1001,0))&"") | F13: =IF($C13="","",INDEX(Inventory!$E$2:$E$1001,MATCH($C13,Inventory!$A$2:$A$1001,0))&"") | G13: =IF($C13="","",INDEX(Inventory!$L$2:$L$1001,MATCH($C13,Inventory!$A$2:$A$1001,0))) | H13: =IF($C13="","",INDEX(Inventory!$M$2:$M$1001,MATCH($C13,Inventory!$A$2:$A$1001,0))&"") | I13: =IF($C13="","",INDEX(Inventory!$F$2:$F$1001,MATCH($C13,Inventory!$A$2:$A$1001,0))&"") | J13: =IF($C13="","",INDEX(Inventory!$O$2:$O$1001,MATCH($C13,Inventory!$A$2:$A$1001,0))&"")
B14: 5 | C14: =IFERROR(INDEX(Inventory!$A$2:$A$1001,MATCH(LARGE(Inventory!$N$2:$N$1001,$B14),Inventory!$N$2:$N$1001,0)),"") | D14: =IF($C14="","",INDEX(Inventory!$C$2:$C$1001,MATCH($C14,Inventory!$A$2:$A$1001,0))&"") | E14: =IF($C14="","",INDEX(Inventory!$D$2:$D$1001,MATCH($C14,Inventory!$A$2:$A$1001,0))&"") | F14: =IF($C14="","",INDEX(Inventory!$E$2:$E$1001,MATCH($C14,Inventory!$A$2:$A$1001,0))&"") | G14: =IF($C14="","",INDEX(Inventory!$L$2:$L$1001,MATCH($C14,Inventory!$A$2:$A$1001,0))) | H14: =IF($C14="","",INDEX(Inventory!$M$2:$M$1001,MATCH($C14,Inventory!$A$2:$A$1001,0))&"") | I14: =IF($C14="","",INDEX(Inventory!$F$2:$F$1001,MATCH($C14,Inventory!$A$2:$A$1001,0))&"") | J14: =IF($C14="","",INDEX(Inventory!$O$2:$O$1001,MATCH($C14,Inventory!$A$2:$A$1001,0))&"")
B15: 6 | C15: =IFERROR(INDEX(Inventory!$A$2:$A$1001,MATCH(LARGE(Inventory!$N$2:$N$1001,$B15),Inventory!$N$2:$N$1001,0)),"") | D15: =IF($C15="","",INDEX(Inventory!$C$2:$C$1001,MATCH($C15,Inventory!$A$2:$A$1001,0))&"") | E15: =IF($C15="","",INDEX(Inventory!$D$2:$D$1001,MATCH($C15,Inventory!$A$2:$A$1001,0))&"") | F15: =IF($C15="","",INDEX(Inventory!$E$2:$E$1001,MATCH($C15,Inventory!$A$2:$A$1001,0))&"") | G15: =IF($C15="","",INDEX(Inventory!$L$2:$L$1001,MATCH($C15,Inventory!$A$2:$A$1001,0))) | H15: =IF($C15="","",INDEX(Inventory!$M$2:$M$1001,MATCH($C15,Inventory!$A$2:$A$1001,0))&"") | I15: =IF($C15="","",INDEX(Inventory!$F$2:$F$1001,MATCH($C15,Inventory!$A$2:$A$1001,0))&"") | J15: =IF($C15="","",INDEX(Inventory!$O$2:$O$1001,MATCH($C15,Inventory!$A$2:$A$1001,0))&"")
B16: 7 | C16: =IFERROR(INDEX(Inventory!$A$2:$A$1001,MATCH(LARGE(Inventory!$N$2:$N$1001,$B16),Inventory!$N$2:$N$1001,0)),"") | D16: =IF($C16="","",INDEX(Inventory!$C$2:$C$1001,MATCH($C16,Inventory!$A$2:$A$1001,0))&"") | E16: =IF($C16="","",INDEX(Inventory!$D$2:$D$1001,MATCH($C16,Inventory!$A$2:$A$1001,0))&"") | F16: =IF($C16="","",INDEX(Inventory!$E$2:$E$1001,MATCH($C16,Inventory!$A$2:$A$1001,0))&"") | G16: =IF($C16="","",INDEX(Inventory!$L$2:$L$1001,MATCH($C16,Inventory!$A$2:$A$1001,0))) | H16: =IF($C16="","",INDEX(Inventory!$M$2:$M$1001,MATCH($C16,Inventory!$A$2:$A$1001,0))&"") | I16: =IF($C16="","",INDEX(Inventory!$F$2:$F$1001,MATCH($C16,Inventory!$A$2:$A$1001,0))&"") | J16: =IF($C16="","",INDEX(Inventory!$O$2:$O$1001,MATCH($C16,Inventory!$A$2:$A$1001,0))&"")
B17: 8 | C17: =IFERROR(INDEX(Inventory!$A$2:$A$1001,MATCH(LARGE(Inventory!$N$2:$N$1001,$B17),Inventory!$N$2:$N$1001,0)),"") | D17: =IF($C17="","",INDEX(Inventory!$C$2:$C$1001,MATCH($C17,Inventory!$A$2:$A$1001,0))&"") | E17: =IF($C17="","",INDEX(Inventory!$D$2:$D$1001,MATCH($C17,Inventory!$A$2:$A$1001,0))&"") | F17: =IF($C17="","",INDEX(Inventory!$E$2:$E$1001,MATCH($C17,Inventory!$A$2:$A$1001,0))&"") | G17: =IF($C17="","",INDEX(Inventory!$L$2:$L$1001,MATCH($C17,Inventory!$A$2:$A$1001,0))) | H17: =IF($C17="","",INDEX(Inventory!$M$2:$M$1001,MATCH($C17,Inventory!$A$2:$A$1001,0))&"") | I17: =IF($C17="","",INDEX(Inventory!$F$2:$F$1001,MATCH($C17,Inventory!$A$2:$A$1001,0))&"") | J17: =IF($C17="","",INDEX(Inventory!$O$2:$O$1001,MATCH($C17,Inventory!$A$2:$A$1001,0))&"")
B18: 9 | C18: =IFERROR(INDEX(Inventory!$A$2:$A$1001,MATCH(LARGE(Inventory!$N$2:$N$1001,$B18),Inventory!$N$2:$N$1001,0)),"") | D18: =IF($C18="","",INDEX(Inventory!$C$2:$C$1001,MATCH($C18,Inventory!$A$2:$A$1001,0))&"") | E18: =IF($C18="","",INDEX(Inventory!$D$2:$D$1001,MATCH($C18,Inventory!$A$2:$A$1001,0))&"") | F18: =IF($C18="","",INDEX(Inventory!$E$2:$E$1001,MATCH($C18,Inventory!$A$2:$A$1001,0))&"") | G18: =IF($C18="","",INDEX(Inventory!$L$2:$L$1001,MATCH($C18,Inventory!$A$2:$A$1001,0))) | H18: =IF($C18="","",INDEX(Inventory!$M$2:$M$1001,MATCH($C18,Inventory!$A$2:$A$1001,0))&"") | I18: =IF($C18="","",INDEX(Inventory!$F$2:$F$1001,MATCH($C18,Inventory!$A$2:$A$1001,0))&"") | J18: =IF($C18="","",INDEX(Inventory!$O$2:$O$1001,MATCH($C18,Inventory!$A$2:$A$1001,0))&"")
B19: 10 | C19: =IFERROR(INDEX(Inventory!$A$2:$A$1001,MATCH(LARGE(Inventory!$N$2:$N$1001,$B19),Inventory!$N$2:$N$1001,0)),"") | D19: =IF($C19="","",INDEX(Inventory!$C$2:$C$1001,MATCH($C19,Inventory!$A$2:$A$1001,0))&"") | E19: =IF($C19="","",INDEX(Inventory!$D$2:$D$1001,MATCH($C19,Inventory!$A$2:$A$1001,0))&"") | F19: =IF($C19="","",INDEX(Inventory!$E$2:$E$1001,MATCH($C19,Inventory!$A$2:$A$1001,0))&"") | G19: =IF($C19="","",INDEX(Inventory!$L$2:$L$1001,MATCH($C19,Inventory!$A$2:$A$1001,0))) | H19: =IF($C19="","",INDEX(Inventory!$M$2:$M$1001,MATCH($C19,Inventory!$A$2:$A$1001,0))&"") | I19: =IF($C19="","",INDEX(Inventory!$F$2:$F$1001,MATCH($C19,Inventory!$A$2:$A$1001,0))&"") | J19: =IF($C19="","",INDEX(Inventory!$O$2:$O$1001,MATCH($C19,Inventory!$A$2:$A$1001,0))&"")
B21: Jira needing attention | E21: Flagged, past due, unmapped, or idle past the stage limit on the Config sheet.
B22: # | C22: Key | D22: Stage | E22: Assignee | F22: Summary | G22: Idle (d) | H22: Health | J22: Why | K22: Say this
B23: 1 | C23: =IFERROR(INDEX(Jira!$A$2:$A$501,MATCH(LARGE(Jira!$R$2:$R$501,$B23),Jira!$R$2:$R$501,0)),"") | D23: =IF($C23="","",INDEX(Jira!$M$2:$M$501,MATCH($C23,Jira!$A$2:$A$501,0))&"") | E23: =IF($C23="","",INDEX(Jira!$F$2:$F$501,MATCH($C23,Jira!$A$2:$A$501,0))&"") | F23: =IF($C23="","",INDEX(Jira!$B$2:$B$501,MATCH($C23,Jira!$A$2:$A$501,0))&"") | G23: =IF($C23="","",INDEX(Jira!$N$2:$N$501,MATCH($C23,Jira!$A$2:$A$501,0))) | H23: =IF($C23="","",INDEX(Jira!$P$2:$P$501,MATCH($C23,Jira!$A$2:$A$501,0))&"") | J23: =IF($C23="","",INDEX(Jira!$Q$2:$Q$501,MATCH($C23,Jira!$A$2:$A$501,0))&"") | K23: =IF($C23="","",INDEX(Jira!$S$2:$S$501,MATCH($C23,Jira!$A$2:$A$501,0))&"")
B24: 2 | C24: =IFERROR(INDEX(Jira!$A$2:$A$501,MATCH(LARGE(Jira!$R$2:$R$501,$B24),Jira!$R$2:$R$501,0)),"") | D24: =IF($C24="","",INDEX(Jira!$M$2:$M$501,MATCH($C24,Jira!$A$2:$A$501,0))&"") | E24: =IF($C24="","",INDEX(Jira!$F$2:$F$501,MATCH($C24,Jira!$A$2:$A$501,0))&"") | F24: =IF($C24="","",INDEX(Jira!$B$2:$B$501,MATCH($C24,Jira!$A$2:$A$501,0))&"") | G24: =IF($C24="","",INDEX(Jira!$N$2:$N$501,MATCH($C24,Jira!$A$2:$A$501,0))) | H24: =IF($C24="","",INDEX(Jira!$P$2:$P$501,MATCH($C24,Jira!$A$2:$A$501,0))&"") | J24: =IF($C24="","",INDEX(Jira!$Q$2:$Q$501,MATCH($C24,Jira!$A$2:$A$501,0))&"") | K24: =IF($C24="","",INDEX(Jira!$S$2:$S$501,MATCH($C24,Jira!$A$2:$A$501,0))&"")
B25: 3 | C25: =IFERROR(INDEX(Jira!$A$2:$A$501,MATCH(LARGE(Jira!$R$2:$R$501,$B25),Jira!$R$2:$R$501,0)),"") | D25: =IF($C25="","",INDEX(Jira!$M$2:$M$501,MATCH($C25,Jira!$A$2:$A$501,0))&"") | E25: =IF($C25="","",INDEX(Jira!$F$2:$F$501,MATCH($C25,Jira!$A$2:$A$501,0))&"") | F25: =IF($C25="","",INDEX(Jira!$B$2:$B$501,MATCH($C25,Jira!$A$2:$A$501,0))&"") | G25: =IF($C25="","",INDEX(Jira!$N$2:$N$501,MATCH($C25,Jira!$A$2:$A$501,0))) | H25: =IF($C25="","",INDEX(Jira!$P$2:$P$501,MATCH($C25,Jira!$A$2:$A$501,0))&"") | J25: =IF($C25="","",INDEX(Jira!$Q$2:$Q$501,MATCH($C25,Jira!$A$2:$A$501,0))&"") | K25: =IF($C25="","",INDEX(Jira!$S$2:$S$501,MATCH($C25,Jira!$A$2:$A$501,0))&"")
B26: 4 | C26: =IFERROR(INDEX(Jira!$A$2:$A$501,MATCH(LARGE(Jira!$R$2:$R$501,$B26),Jira!$R$2:$R$501,0)),"") | D26: =IF($C26="","",INDEX(Jira!$M$2:$M$501,MATCH($C26,Jira!$A$2:$A$501,0))&"") | E26: =IF($C26="","",INDEX(Jira!$F$2:$F$501,MATCH($C26,Jira!$A$2:$A$501,0))&"") | F26: =IF($C26="","",INDEX(Jira!$B$2:$B$501,MATCH($C26,Jira!$A$2:$A$501,0))&"") | G26: =IF($C26="","",INDEX(Jira!$N$2:$N$501,MATCH($C26,Jira!$A$2:$A$501,0))) | H26: =IF($C26="","",INDEX(Jira!$P$2:$P$501,MATCH($C26,Jira!$A$2:$A$501,0))&"") | J26: =IF($C26="","",INDEX(Jira!$Q$2:$Q$501,MATCH($C26,Jira!$A$2:$A$501,0))&"") | K26: =IF($C26="","",INDEX(Jira!$S$2:$S$501,MATCH($C26,Jira!$A$2:$A$501,0))&"")
B27: 5 | C27: =IFERROR(INDEX(Jira!$A$2:$A$501,MATCH(LARGE(Jira!$R$2:$R$501,$B27),Jira!$R$2:$R$501,0)),"") | D27: =IF($C27="","",INDEX(Jira!$M$2:$M$501,MATCH($C27,Jira!$A$2:$A$501,0))&"") | E27: =IF($C27="","",INDEX(Jira!$F$2:$F$501,MATCH($C27,Jira!$A$2:$A$501,0))&"") | F27: =IF($C27="","",INDEX(Jira!$B$2:$B$501,MATCH($C27,Jira!$A$2:$A$501,0))&"") | G27: =IF($C27="","",INDEX(Jira!$N$2:$N$501,MATCH($C27,Jira!$A$2:$A$501,0))) | H27: =IF($C27="","",INDEX(Jira!$P$2:$P$501,MATCH($C27,Jira!$A$2:$A$501,0))&"") | J27: =IF($C27="","",INDEX(Jira!$Q$2:$Q$501,MATCH($C27,Jira!$A$2:$A$501,0))&"") | K27: =IF($C27="","",INDEX(Jira!$S$2:$S$501,MATCH($C27,Jira!$A$2:$A$501,0))&"")
B28: 6 | C28: =IFERROR(INDEX(Jira!$A$2:$A$501,MATCH(LARGE(Jira!$R$2:$R$501,$B28),Jira!$R$2:$R$501,0)),"") | D28: =IF($C28="","",INDEX(Jira!$M$2:$M$501,MATCH($C28,Jira!$A$2:$A$501,0))&"") | E28: =IF($C28="","",INDEX(Jira!$F$2:$F$501,MATCH($C28,Jira!$A$2:$A$501,0))&"") | F28: =IF($C28="","",INDEX(Jira!$B$2:$B$501,MATCH($C28,Jira!$A$2:$A$501,0))&"") | G28: =IF($C28="","",INDEX(Jira!$N$2:$N$501,MATCH($C28,Jira!$A$2:$A$501,0))) | H28: =IF($C28="","",INDEX(Jira!$P$2:$P$501,MATCH($C28,Jira!$A$2:$A$501,0))&"") | J28: =IF($C28="","",INDEX(Jira!$Q$2:$Q$501,MATCH($C28,Jira!$A$2:$A$501,0))&"") | K28: =IF($C28="","",INDEX(Jira!$S$2:$S$501,MATCH($C28,Jira!$A$2:$A$501,0))&"")
B29: 7 | C29: =IFERROR(INDEX(Jira!$A$2:$A$501,MATCH(LARGE(Jira!$R$2:$R$501,$B29),Jira!$R$2:$R$501,0)),"") | D29: =IF($C29="","",INDEX(Jira!$M$2:$M$501,MATCH($C29,Jira!$A$2:$A$501,0))&"") | E29: =IF($C29="","",INDEX(Jira!$F$2:$F$501,MATCH($C29,Jira!$A$2:$A$501,0))&"") | F29: =IF($C29="","",INDEX(Jira!$B$2:$B$501,MATCH($C29,Jira!$A$2:$A$501,0))&"") | G29: =IF($C29="","",INDEX(Jira!$N$2:$N$501,MATCH($C29,Jira!$A$2:$A$501,0))) | H29: =IF($C29="","",INDEX(Jira!$P$2:$P$501,MATCH($C29,Jira!$A$2:$A$501,0))&"") | J29: =IF($C29="","",INDEX(Jira!$Q$2:$Q$501,MATCH($C29,Jira!$A$2:$A$501,0))&"") | K29: =IF($C29="","",INDEX(Jira!$S$2:$S$501,MATCH($C29,Jira!$A$2:$A$501,0))&"")
B30: 8 | C30: =IFERROR(INDEX(Jira!$A$2:$A$501,MATCH(LARGE(Jira!$R$2:$R$501,$B30),Jira!$R$2:$R$501,0)),"") | D30: =IF($C30="","",INDEX(Jira!$M$2:$M$501,MATCH($C30,Jira!$A$2:$A$501,0))&"") | E30: =IF($C30="","",INDEX(Jira!$F$2:$F$501,MATCH($C30,Jira!$A$2:$A$501,0))&"") | F30: =IF($C30="","",INDEX(Jira!$B$2:$B$501,MATCH($C30,Jira!$A$2:$A$501,0))&"") | G30: =IF($C30="","",INDEX(Jira!$N$2:$N$501,MATCH($C30,Jira!$A$2:$A$501,0))) | H30: =IF($C30="","",INDEX(Jira!$P$2:$P$501,MATCH($C30,Jira!$A$2:$A$501,0))&"") | J30: =IF($C30="","",INDEX(Jira!$Q$2:$Q$501,MATCH($C30,Jira!$A$2:$A$501,0))&"") | K30: =IF($C30="","",INDEX(Jira!$S$2:$S$501,MATCH($C30,Jira!$A$2:$A$501,0))&"")
B31: 9 | C31: =IFERROR(INDEX(Jira!$A$2:$A$501,MATCH(LARGE(Jira!$R$2:$R$501,$B31),Jira!$R$2:$R$501,0)),"") | D31: =IF($C31="","",INDEX(Jira!$M$2:$M$501,MATCH($C31,Jira!$A$2:$A$501,0))&"") | E31: =IF($C31="","",INDEX(Jira!$F$2:$F$501,MATCH($C31,Jira!$A$2:$A$501,0))&"") | F31: =IF($C31="","",INDEX(Jira!$B$2:$B$501,MATCH($C31,Jira!$A$2:$A$501,0))&"") | G31: =IF($C31="","",INDEX(Jira!$N$2:$N$501,MATCH($C31,Jira!$A$2:$A$501,0))) | H31: =IF($C31="","",INDEX(Jira!$P$2:$P$501,MATCH($C31,Jira!$A$2:$A$501,0))&"") | J31: =IF($C31="","",INDEX(Jira!$Q$2:$Q$501,MATCH($C31,Jira!$A$2:$A$501,0))&"") | K31: =IF($C31="","",INDEX(Jira!$S$2:$S$501,MATCH($C31,Jira!$A$2:$A$501,0))&"")
B32: 10 | C32: =IFERROR(INDEX(Jira!$A$2:$A$501,MATCH(LARGE(Jira!$R$2:$R$501,$B32),Jira!$R$2:$R$501,0)),"") | D32: =IF($C32="","",INDEX(Jira!$M$2:$M$501,MATCH($C32,Jira!$A$2:$A$501,0))&"") | E32: =IF($C32="","",INDEX(Jira!$F$2:$F$501,MATCH($C32,Jira!$A$2:$A$501,0))&"") | F32: =IF($C32="","",INDEX(Jira!$B$2:$B$501,MATCH($C32,Jira!$A$2:$A$501,0))&"") | G32: =IF($C32="","",INDEX(Jira!$N$2:$N$501,MATCH($C32,Jira!$A$2:$A$501,0))) | H32: =IF($C32="","",INDEX(Jira!$P$2:$P$501,MATCH($C32,Jira!$A$2:$A$501,0))&"") | J32: =IF($C32="","",INDEX(Jira!$Q$2:$Q$501,MATCH($C32,Jira!$A$2:$A$501,0))&"") | K32: =IF($C32="","",INDEX(Jira!$S$2:$S$501,MATCH($C32,Jira!$A$2:$A$501,0))&"")
B34: Pipeline by stage | E34: Open Jira issues per stage.
C35: Stage | D35: Open | E35: Attention | F35: Stale after
C36: Intake | D36: =COUNTIF(Jira!$M:$M,$C36) -> 0 | E36: =COUNTIFS(Jira!$M:$M,$C36,Jira!$P:$P,"Critical")+COUNTIFS(Jira!$M:$M,$C36,Jira!$P:$P,"Warning") -> 0 | F36: =INDEX(StageStale,MATCH($C36,StageName,0))&" days" -> 7 days
C37: Triage | D37: =COUNTIF(Jira!$M:$M,$C37) -> 0 | E37: =COUNTIFS(Jira!$M:$M,$C37,Jira!$P:$P,"Critical")+COUNTIFS(Jira!$M:$M,$C37,Jira!$P:$P,"Warning") -> 0 | F37: =INDEX(StageStale,MATCH($C37,StageName,0))&" days" -> 7 days
C38: Discovery | D38: =COUNTIF(Jira!$M:$M,$C38) -> 0 | E38: =COUNTIFS(Jira!$M:$M,$C38,Jira!$P:$P,"Critical")+COUNTIFS(Jira!$M:$M,$C38,Jira!$P:$P,"Warning") -> 0 | F38: =INDEX(StageStale,MATCH($C38,StageName,0))&" days" -> 10 days
C39: Design | D39: =COUNTIF(Jira!$M:$M,$C39) -> 0 | E39: =COUNTIFS(Jira!$M:$M,$C39,Jira!$P:$P,"Critical")+COUNTIFS(Jira!$M:$M,$C39,Jira!$P:$P,"Warning") -> 0 | F39: =INDEX(StageStale,MATCH($C39,StageName,0))&" days" -> 14 days
C40: Approval | D40: =COUNTIF(Jira!$M:$M,$C40) -> 0 | E40: =COUNTIFS(Jira!$M:$M,$C40,Jira!$P:$P,"Critical")+COUNTIFS(Jira!$M:$M,$C40,Jira!$P:$P,"Warning") -> 0 | F40: =INDEX(StageStale,MATCH($C40,StageName,0))&" days" -> 14 days
C41: Delivery | D41: =COUNTIF(Jira!$M:$M,$C41) -> 0 | E41: =COUNTIFS(Jira!$M:$M,$C41,Jira!$P:$P,"Critical")+COUNTIFS(Jira!$M:$M,$C41,Jira!$P:$P,"Warning") -> 0 | F41: =INDEX(StageStale,MATCH($C41,StageName,0))&" days" -> 14 days
C42: Scale | D42: =COUNTIF(Jira!$M:$M,$C42) -> 0 | E42: =COUNTIFS(Jira!$M:$M,$C42,Jira!$P:$P,"Critical")+COUNTIFS(Jira!$M:$M,$C42,Jira!$P:$P,"Warning") -> 0 | F42: =INDEX(StageStale,MATCH($C42,StageName,0))&" days" -> 14 days
C43: Value | D43: =COUNTIF(Jira!$M:$M,$C43) -> 0 | E43: =COUNTIFS(Jira!$M:$M,$C43,Jira!$P:$P,"Critical")+COUNTIFS(Jira!$M:$M,$C43,Jira!$P:$P,"Warning") -> 0 | F43: =INDEX(StageStale,MATCH($C43,StageName,0))&" days" -> 45 days
C44: Unmapped | D44: =COUNTIF(Jira!$M:$M,$C44) -> 0 | E44: =COUNTIFS(Jira!$M:$M,$C44,Jira!$P:$P,"Critical")+COUNTIFS(Jira!$M:$M,$C44,Jira!$P:$P,"Warning") -> 0 | F44: add to Config map
...

Sheet Inventory
A1: ID | B1: Date | C1: Type | D1: Topic | E1: Summary | F1: From | G1: Channel | H1: Confidence | I1: Ref | J1: Jira | K1: State | L1: Age (days) | M1: Severity | N1: Rank key | O1: Say this
K2: =IF($A2="","",IF(OR($C2="Decision",$C2="Conflict"),IF(COUNTIFS($I$2:$I$1001,$A2,$C$2:$C$1001,"Resolved")=0,"Open","Closed"),IF(AND($H2="Unconfirmed",OR($C2="New",$C2="Know")),IF(COUNTIFS($I$2:$I$1001,$A2,$C$2:$C$1001,"Confirmed")=0,"Unconfirmed","Confirmed"),"Logged"))) | L2: =IF($A2="","",AsOf-$B2) | M2: =IF($K2="Open",IF($C2="Conflict","Critical",IF($L2>=DecisionCritical,"Critical",IF($L2>=DecisionWarn,"Warning","On track"))),IF($K2="Unconfirmed",IF($L2>=UnconfirmedWarn,"Warning","On track"),"")) | N2: =IF($M2="","",IF($M2="Critical",3000,IF($M2="Warning",2000,1000))+$L2+ROW()/100000) | O2: =IF($K2="Open",IF($C2="Conflict","decide "&$A2&": <which version stands>","decide "&$A2&": <outcome>"),IF($K2="Unconfirmed","confirm "&$A2,""))
K3: =IF($A3="","",IF(OR($C3="Decision",$C3="Conflict"),IF(COUNTIFS($I$2:$I$1001,$A3,$C$2:$C$1001,"Resolved")=0,"Open","Closed"),IF(AND($H3="Unconfirmed",OR($C3="New",$C3="Know")),IF(COUNTIFS($I$2:$I$1001,$A3,$C$2:$C$1001,"Confirmed")=0,"Unconfirmed","Confirmed"),"Logged"))) | L3: =IF($A3="","",AsOf-$B3) | M3: =IF($K3="Open",IF($C3="Conflict","Critical",IF($L3>=DecisionCritical,"Critical",IF($L3>=DecisionWarn,"Warning","On track"))),IF($K3="Unconfirmed",IF($L3>=UnconfirmedWarn,"Warning","On track"),"")) | N3: =IF($M3="","",IF($M3="Critical",3000,IF($M3="Warning",2000,1000))+$L3+ROW()/100000) | O3: =IF($K3="Open",IF($C3="Conflict","decide "&$A3&": <which version stands>","decide "&$A3&": <outcome>"),IF($K3="Unconfirmed","confirm "&$A3,""))
K4: =IF($A4="","",IF(OR($C4="Decision",$C4="Conflict"),IF(COUNTIFS($I$2:$I$1001,$A4,$C$2:$C$1001,"Resolved")=0,"Open","Closed"),IF(AND($H4="Unconfirmed",OR($C4="New",$C4="Know")),IF(COUNTIFS($I$2:$I$1001,$A4,$C$2:$C$1001,"Confirmed")=0,"Unconfirmed","Confirmed"),"Logged"))) | L4: =IF($A4="","",AsOf-$B4) | M4: =IF($K4="Open",IF($C4="Conflict","Critical",IF($L4>=DecisionCritical,"Critical",IF($L4>=DecisionWarn,"Warning","On track"))),IF($K4="Unconfirmed",IF($L4>=UnconfirmedWarn,"Warning","On track"),"")) | N4: =IF($M4="","",IF($M4="Critical",3000,IF($M4="Warning",2000,1000))+$L4+ROW()/100000) | O4: =IF($K4="Open",IF($C4="Conflict","decide "&$A4&": <which version stands>","decide "&$A4&": <outcome>"),IF($K4="Unconfirmed","confirm "&$A4,""))
K5: =IF($A5="","",IF(OR($C5="Decision",$C5="Conflict"),IF(COUNTIFS($I$2:$I$1001,$A5,$C$2:$C$1001,"Resolved")=0,"Open","Closed"),IF(AND($H5="Unconfirmed",OR($C5="New",$C5="Know")),IF(COUNTIFS($I$2:$I$1001,$A5,$C$2:$C$1001,"Confirmed")=0,"Unconfirmed","Confirmed"),"Logged"))) | L5: =IF($A5="","",AsOf-$B5) | M5: =IF($K5="Open",IF($C5="Conflict","Critical",IF($L5>=DecisionCritical,"Critical",IF($L5>=DecisionWarn,"Warning","On track"))),IF($K5="Unconfirmed",IF($L5>=UnconfirmedWarn,"Warning","On track"),"")) | N5: =IF($M5="","",IF($M5="Critical",3000,IF($M5="Warning",2000,1000))+$L5+ROW()/100000) | O5: =IF($K5="Open",IF($C5="Conflict","decide "&$A5&": <which version stands>","decide "&$A5&": <outcome>"),IF($K5="Unconfirmed","confirm "&$A5,""))
K6: =IF($A6="","",IF(OR($C6="Decision",$C6="Conflict"),IF(COUNTIFS($I$2:$I$1001,$A6,$C$2:$C$1001,"Resolved")=0,"Open","Closed"),IF(AND($H6="Unconfirmed",OR($C6="New",$C6="Know")),IF(COUNTIFS($I$2:$I$1001,$A6,$C$2:$C$1001,"Confirmed")=0,"Unconfirmed","Confirmed"),"Logged"))) | L6: =IF($A6="","",AsOf-$B6) | M6: =IF($K6="Open",IF($C6="Conflict","Critical",IF($L6>=DecisionCritical,"Critical",IF($L6>=DecisionWarn,"Warning","On track"))),IF($K6="Unconfirmed",IF($L6>=UnconfirmedWarn,"Warning","On track"),"")) | N6: =IF($M6="","",IF($M6="Critical",3000,IF($M6="Warning",2000,1000))+$L6+ROW()/100000) | O6: =IF($K6="Open",IF($C6="Conflict","decide "&$A6&": <which version stands>","decide "&$A6&": <outcome>"),IF($K6="Unconfirmed","confirm "&$A6,""))
K7: =IF($A7="","",IF(OR($C7="Decision",$C7="Conflict"),IF(COUNTIFS($I$2:$I$1001,$A7,$C$2:$C$1001,"Resolved")=0,"Open","Closed"),IF(AND($H7="Unconfirmed",OR($C7="New",$C7="Know")),IF(COUNTIFS($I$2:$I$1001,$A7,$C$2:$C$1001,"Confirmed")=0,"Unconfirmed","Confirmed"),"Logged"))) | L7: =IF($A7="","",AsOf-$B7) | M7: =IF($K7="Open",IF($C7="Conflict","Critical",IF($L7>=DecisionCritical,"Critical",IF($L7>=DecisionWarn,"Warning","On track"))),IF($K7="Unconfirmed",IF($L7>=UnconfirmedWarn,"Warning","On track"),"")) | N7: =IF($M7="","",IF($M7="Critical",3000,IF($M7="Warning",2000,1000))+$L7+ROW()/100000) | O7: =IF($K7="Open",IF($C7="Conflict","decide "&$A7&": <which version stands>","decide "&$A7&": <outcome>"),IF($K7="Unconfirmed","confirm "&$A7,""))
K8: =IF($A8="","",IF(OR($C8="Decision",$C8="Conflict"),IF(COUNTIFS($I$2:$I$1001,$A8,$C$2:$C$1001,"Resolved")=0,"Open","Closed"),IF(AND($H8="Unconfirmed",OR($C8="New",$C8="Know")),IF(COUNTIFS($I$2:$I$1001,$A8,$C$2:$C$1001,"Confirmed")=0,"Unconfirmed","Confirmed"),"Logged"))) | L8: =IF($A8="","",AsOf-$B8) | M8: =IF($K8="Open",IF($C8="Conflict","Critical",IF($L8>=DecisionCritical,"Critical",IF($L8>=DecisionWarn,"Warning","On track"))),IF($K8="Unconfirmed",IF($L8>=UnconfirmedWarn,"Warning","On track"),"")) | N8: =IF($M8="","",IF($M8="Critical",3000,IF($M8="Warning",2000,1000))+$L8+ROW()/100000) | O8: =IF($K8="Open",IF($C8="Conflict","decide "&$A8&": <which version stands>","decide "&$A8&": <outcome>"),IF($K8="Unconfirmed","confirm "&$A8,""))
K9: =IF($A9="","",IF(OR($C9="Decision",$C9="Conflict"),IF(COUNTIFS($I$2:$I$1001,$A9,$C$2:$C$1001,"Resolved")=0,"Open","Closed"),IF(AND($H9="Unconfirmed",OR($C9="New",$C9="Know")),IF(COUNTIFS($I$2:$I$1001,$A9,$C$2:$C$1001,"Confirmed")=0,"Unconfirmed","Confirmed"),"Logged"))) | L9: =IF($A9="","",AsOf-$B9) | M9: =IF($K9="Open",IF($C9="Conflict","Critical",IF($L9>=DecisionCritical,"Critical",IF($L9>=DecisionWarn,"Warning","On track"))),IF($K9="Unconfirmed",IF($L9>=UnconfirmedWarn,"Warning","On track"),"")) | N9: =IF($M9="","",IF($M9="Critical",3000,IF($M9="Warning",2000,1000))+$L9+ROW()/100000) | O9: =IF($K9="Open",IF($C9="Conflict","decide "&$A9&": <which version stands>","decide "&$A9&": <outcome>"),IF($K9="Unconfirmed","confirm "&$A9,""))
K10: =IF($A10="","",IF(OR($C10="Decision",$C10="Conflict"),IF(COUNTIFS($I$2:$I$1001,$A10,$C$2:$C$1001,"Resolved")=0,"Open","Closed"),IF(AND($H10="Unconfirmed",OR($C10="New",$C10="Know")),IF(COUNTIFS($I$2:$I$1001,$A10,$C$2:$C$1001,"Confirmed")=0,"Unconfirmed","Confirmed"),"Logged"))) | L10: =IF($A10="","",AsOf-$B10) | M10: =IF($K10="Open",IF($C10="Conflict","Critical",IF($L10>=DecisionCritical,"Critical",IF($L10>=DecisionWarn,"Warning","On track"))),IF($K10="Unconfirmed",IF($L10>=UnconfirmedWarn,"Warning","On track"),"")) | N10: =IF($M10="","",IF($M10="Critical",3000,IF($M10="Warning",2000,1000))+$L10+ROW()/100000) | O10: =IF($K10="Open",IF($C10="Conflict","decide "&$A10&": <which version stands>","decide "&$A10&": <outcome>"),IF($K10="Unconfirmed","confirm "&$A10,""))
K11: =IF($A11="","",IF(OR($C11="Decision",$C11="Conflict"),IF(COUNTIFS($I$2:$I$1001,$A11,$C$2:$C$1001,"Resolved")=0,"Open","Closed"),IF(AND($H11="Unconfirmed",OR($C11="New",$C11="Know")),IF(COUNTIFS($I$2:$I$1001,$A11,$C$2:$C$1001,"Confirmed")=0,"Unconfirmed","Confirmed"),"Logged"))) | L11: =IF($A11="","",AsOf-$B11) | M11: =IF($K11="Open",IF($C11="Conflict","Critical",IF($L11>=DecisionCritical,"Critical",IF($L11>=DecisionWarn,"Warning","On track"))),IF($K11="Unconfirmed",IF($L11>=UnconfirmedWarn,"Warning","On track"),"")) | N11: =IF($M11="","",IF($M11="Critical",3000,IF($M11="Warning",2000,1000))+$L11+ROW()/100000) | O11: =IF($K11="Open",IF($C11="Conflict","decide "&$A11&": <which version stands>","decide "&$A11&": <outcome>"),IF($K11="Unconfirmed","confirm "&$A11,""))
K12: =IF($A12="","",IF(OR($C12="Decision",$C12="Conflict"),IF(COUNTIFS($I$2:$I$1001,$A12,$C$2:$C$1001,"Resolved")=0,"Open","Closed"),IF(AND($H12="Unconfirmed",OR($C12="New",$C12="Know")),IF(COUNTIFS($I$2:$I$1001,$A12,$C$2:$C$1001,"Confirmed")=0,"Unconfirmed","Confirmed"),"Logged"))) | L12: =IF($A12="","",AsOf-$B12) | M12: =IF($K12="Open",IF($C12="Conflict","Critical",IF($L12>=DecisionCritical,"Critical",IF($L12>=DecisionWarn,"Warning","On track"))),IF($K12="Unconfirmed",IF($L12>=UnconfirmedWarn,"Warning","On track"),"")) | N12: =IF($M12="","",IF($M12="Critical",3000,IF($M12="Warning",2000,1000))+$L12+ROW()/100000) | O12: =IF($K12="Open",IF($C12="Conflict","decide "&$A12&": <which version stands>","decide "&$A12&": <outcome>"),IF($K12="Unconfirmed","confirm "&$A12,""))
K13: =IF($A13="","",IF(OR($C13="Decision",$C13="Conflict"),IF(COUNTIFS($I$2:$I$1001,$A13,$C$2:$C$1001,"Resolved")=0,"Open","Closed"),IF(AND($H13="Unconfirmed",OR($C13="New",$C13="Know")),IF(COUNTIFS($I$2:$I$1001,$A13,$C$2:$C$1001,"Confirmed")=0,"Unconfirmed","Confirmed"),"Logged"))) | L13: =IF($A13="","",AsOf-$B13) | M13: =IF($K13="Open",IF($C13="Conflict","Critical",IF($L13>=DecisionCritical,"Critical",IF($L13>=DecisionWarn,"Warning","On track"))),IF($K13="Unconfirmed",IF($L13>=UnconfirmedWarn,"Warning","On track"),"")) | N13: =IF($M13="","",IF($M13="Critical",3000,IF($M13="Warning",2000,1000))+$L13+ROW()/100000) | O13: =IF($K13="Open",IF($C13="Conflict","decide "&$A13&": <which version stands>","decide "&$A13&": <outcome>"),IF($K13="Unconfirmed","confirm "&$A13,""))
... K1001: =IF($A1001="","",IF(OR($C1001="Decision",$C1001="Conflict"),IF(COUNTIFS($I$2:$I$1001,$A1001,$C$2:$C$1001,"Resolved")=0,"Open","Closed"),IF(AND($H1001="Unconfirmed",OR($C1001="New",$C1001="Know")),IF(COUNTIFS($I$2:$I$1001,$A1001,$C$2:$C$1001,"Confirmed")=0,"Unconfirmed","Confirmed"),"Logged"))) | L1001: =IF($A1001="","",AsOf-$B1001) | M1001: =IF($K1001="Open",IF($C1001="Conflict","Critical",IF($L1001>=DecisionCritical,"Critical",IF($L1001>=DecisionWarn,"Warning","On track"))),IF($K1001="Unconfirmed",IF($L1001>=UnconfirmedWarn,"Warning","On track"),"")) | N1001: =IF($M1001="","",IF($M1001="Critical",3000,IF($M1001="Warning",2000,1000))+$L1001+ROW()/100000) | O1001: =IF($K1001="Open",IF($C1001="Conflict","decide "&$A1001&": <which version stands>","decide "&$A1001&": <outcome>"),IF($K1001="Unconfirmed","confirm "&$A1001,""))

Sheet Jira
A1: Key | B1: Summary | C1: Status | D1: Type | E1: Priority | F1: Assignee | G1: Created | H1: Updated | I1: Due | J1: Flagged | K1: Labels | L1: Topic | M1: Stage | N1: Days idle | O1: Stale after | P1: Health | Q1: Why | R1: Rank key | S1: Say this | T1: Link
M2: =IF($A2="","",IFERROR(INDEX(MapStage,MATCH($C2,MapStatus,0)),"Unmapped")) | N2: =IF($A2="","",AsOf-$H2) | O2: =IF(OR($M2="",$M2="Closed",$M2="Unmapped"),"",INDEX(StageStale,MATCH($M2,StageName,0))) | P2: =IF($A2="","",IF($M2="Closed","Closed",IF($J2="Y","Critical",IF(AND($I2<>"",$I2<AsOf),"Critical",IF($M2="Unmapped","Warning",IF($N2>2*$O2,"Critical",IF($N2>$O2,"Warning","On track"))))))) | Q2: =IF(OR($P2="",$P2="Closed",$P2="On track"),"",IF($J2="Y","Flagged as an impediment",IF(AND($I2<>"",$I2<AsOf),"Past due since "&TEXT($I2,"yyyy-mm-dd"),IF($M2="Unmapped","Status '"&$C2&"' is not in the Config map","No update in "&$N2&" days (limit "&$O2&")")))) | R2: =IF(OR($P2="",$P2="Closed",$P2="On track"),"",IF($P2="Critical",3000,2000)+$N2+ROW()/100000) | S2: =IF($R2="","","draft Jira update for "&$A2) | T2: =IF($A2="","",HYPERLINK(JiraSite&"/browse/"&$A2,"open"))
M3: =IF($A3="","",IFERROR(INDEX(MapStage,MATCH($C3,MapStatus,0)),"Unmapped")) | N3: =IF($A3="","",AsOf-$H3) | O3: =IF(OR($M3="",$M3="Closed",$M3="Unmapped"),"",INDEX(StageStale,MATCH($M3,StageName,0))) | P3: =IF($A3="","",IF($M3="Closed","Closed",IF($J3="Y","Critical",IF(AND($I3<>"",$I3<AsOf),"Critical",IF($M3="Unmapped","Warning",IF($N3>2*$O3,"Critical",IF($N3>$O3,"Warning","On track"))))))) | Q3: =IF(OR($P3="",$P3="Closed",$P3="On track"),"",IF($J3="Y","Flagged as an impediment",IF(AND($I3<>"",$I3<AsOf),"Past due since "&TEXT($I3,"yyyy-mm-dd"),IF($M3="Unmapped","Status '"&$C3&"' is not in the Config map","No update in "&$N3&" days (limit "&$O3&")")))) | R3: =IF(OR($P3="",$P3="Closed",$P3="On track"),"",IF($P3="Critical",3000,2000)+$N3+ROW()/100000) | S3: =IF($R3="","","draft Jira update for "&$A3) | T3: =IF($A3="","",HYPERLINK(JiraSite&"/browse/"&$A3,"open"))
M4: =IF($A4="","",IFERROR(INDEX(MapStage,MATCH($C4,MapStatus,0)),"Unmapped")) | N4: =IF($A4="","",AsOf-$H4) | O4: =IF(OR($M4="",$M4="Closed",$M4="Unmapped"),"",INDEX(StageStale,MATCH($M4,StageName,0))) | P4: =IF($A4="","",IF($M4="Closed","Closed",IF($J4="Y","Critical",IF(AND($I4<>"",$I4<AsOf),"Critical",IF($M4="Unmapped","Warning",IF($N4>2*$O4,"Critical",IF($N4>$O4,"Warning","On track"))))))) | Q4: =IF(OR($P4="",$P4="Closed",$P4="On track"),"",IF($J4="Y","Flagged as an impediment",IF(AND($I4<>"",$I4<AsOf),"Past due since "&TEXT($I4,"yyyy-mm-dd"),IF($M4="Unmapped","Status '"&$C4&"' is not in the Config map","No update in "&$N4&" days (limit "&$O4&")")))) | R4: =IF(OR($P4="",$P4="Closed",$P4="On track"),"",IF($P4="Critical",3000,2000)+$N4+ROW()/100000) | S4: =IF($R4="","","draft Jira update for "&$A4) | T4: =IF($A4="","",HYPERLINK(JiraSite&"/browse/"&$A4,"open"))
M5: =IF($A5="","",IFERROR(INDEX(MapStage,MATCH($C5,MapStatus,0)),"Unmapped")) | N5: =IF($A5="","",AsOf-$H5) | O5: =IF(OR($M5="",$M5="Closed",$M5="Unmapped"),"",INDEX(StageStale,MATCH($M5,StageName,0))) | P5: =IF($A5="","",IF($M5="Closed","Closed",IF($J5="Y","Critical",IF(AND($I5<>"",$I5<AsOf),"Critical",IF($M5="Unmapped","Warning",IF($N5>2*$O5,"Critical",IF($N5>$O5,"Warning","On track"))))))) | Q5: =IF(OR($P5="",$P5="Closed",$P5="On track"),"",IF($J5="Y","Flagged as an impediment",IF(AND($I5<>"",$I5<AsOf),"Past due since "&TEXT($I5,"yyyy-mm-dd"),IF($M5="Unmapped","Status '"&$C5&"' is not in the Config map","No update in "&$N5&" days (limit "&$O5&")")))) | R5: =IF(OR($P5="",$P5="Closed",$P5="On track"),"",IF($P5="Critical",3000,2000)+$N5+ROW()/100000) | S5: =IF($R5="","","draft Jira update for "&$A5) | T5: =IF($A5="","",HYPERLINK(JiraSite&"/browse/"&$A5,"open"))
M6: =IF($A6="","",IFERROR(INDEX(MapStage,MATCH($C6,MapStatus,0)),"Unmapped")) | N6: =IF($A6="","",AsOf-$H6) | O6: =IF(OR($M6="",$M6="Closed",$M6="Unmapped"),"",INDEX(StageStale,MATCH($M6,StageName,0))) | P6: =IF($A6="","",IF($M6="Closed","Closed",IF($J6="Y","Critical",IF(AND($I6<>"",$I6<AsOf),"Critical",IF($M6="Unmapped","Warning",IF($N6>2*$O6,"Critical",IF($N6>$O6,"Warning","On track"))))))) | Q6: =IF(OR($P6="",$P6="Closed",$P6="On track"),"",IF($J6="Y","Flagged as an impediment",IF(AND($I6<>"",$I6<AsOf),"Past due since "&TEXT($I6,"yyyy-mm-dd"),IF($M6="Unmapped","Status '"&$C6&"' is not in the Config map","No update in "&$N6&" days (limit "&$O6&")")))) | R6: =IF(OR($P6="",$P6="Closed",$P6="On track"),"",IF($P6="Critical",3000,2000)+$N6+ROW()/100000) | S6: =IF($R6="","","draft Jira update for "&$A6) | T6: =IF($A6="","",HYPERLINK(JiraSite&"/browse/"&$A6,"open"))
M7: =IF($A7="","",IFERROR(INDEX(MapStage,MATCH($C7,MapStatus,0)),"Unmapped")) | N7: =IF($A7="","",AsOf-$H7) | O7: =IF(OR($M7="",$M7="Closed",$M7="Unmapped"),"",INDEX(StageStale,MATCH($M7,StageName,0))) | P7: =IF($A7="","",IF($M7="Closed","Closed",IF($J7="Y","Critical",IF(AND($I7<>"",$I7<AsOf),"Critical",IF($M7="Unmapped","Warning",IF($N7>2*$O7,"Critical",IF($N7>$O7,"Warning","On track"))))))) | Q7: =IF(OR($P7="",$P7="Closed",$P7="On track"),"",IF($J7="Y","Flagged as an impediment",IF(AND($I7<>"",$I7<AsOf),"Past due since "&TEXT($I7,"yyyy-mm-dd"),IF($M7="Unmapped","Status '"&$C7&"' is not in the Config map","No update in "&$N7&" days (limit "&$O7&")")))) | R7: =IF(OR($P7="",$P7="Closed",$P7="On track"),"",IF($P7="Critical",3000,2000)+$N7+ROW()/100000) | S7: =IF($R7="","","draft Jira update for "&$A7) | T7: =IF($A7="","",HYPERLINK(JiraSite&"/browse/"&$A7,"open"))
M8: =IF($A8="","",IFERROR(INDEX(MapStage,MATCH($C8,MapStatus,0)),"Unmapped")) | N8: =IF($A8="","",AsOf-$H8) | O8: =IF(OR($M8="",$M8="Closed",$M8="Unmapped"),"",INDEX(StageStale,MATCH($M8,StageName,0))) | P8: =IF($A8="","",IF($M8="Closed","Closed",IF($J8="Y","Critical",IF(AND($I8<>"",$I8<AsOf),"Critical",IF($M8="Unmapped","Warning",IF($N8>2*$O8,"Critical",IF($N8>$O8,"Warning","On track"))))))) | Q8: =IF(OR($P8="",$P8="Closed",$P8="On track"),"",IF($J8="Y","Flagged as an impediment",IF(AND($I8<>"",$I8<AsOf),"Past due since "&TEXT($I8,"yyyy-mm-dd"),IF($M8="Unmapped","Status '"&$C8&"' is not in the Config map","No update in "&$N8&" days (limit "&$O8&")")))) | R8: =IF(OR($P8="",$P8="Closed",$P8="On track"),"",IF($P8="Critical",3000,2000)+$N8+ROW()/100000) | S8: =IF($R8="","","draft Jira update for "&$A8) | T8: =IF($A8="","",HYPERLINK(JiraSite&"/browse/"&$A8,"open"))
M9: =IF($A9="","",IFERROR(INDEX(MapStage,MATCH($C9,MapStatus,0)),"Unmapped")) | N9: =IF($A9="","",AsOf-$H9) | O9: =IF(OR($M9="",$M9="Closed",$M9="Unmapped"),"",INDEX(StageStale,MATCH($M9,StageName,0))) | P9: =IF($A9="","",IF($M9="Closed","Closed",IF($J9="Y","Critical",IF(AND($I9<>"",$I9<AsOf),"Critical",IF($M9="Unmapped","Warning",IF($N9>2*$O9,"Critical",IF($N9>$O9,"Warning","On track"))))))) | Q9: =IF(OR($P9="",$P9="Closed",$P9="On track"),"",IF($J9="Y","Flagged as an impediment",IF(AND($I9<>"",$I9<AsOf),"Past due since "&TEXT($I9,"yyyy-mm-dd"),IF($M9="Unmapped","Status '"&$C9&"' is not in the Config map","No update in "&$N9&" days (limit "&$O9&")")))) | R9: =IF(OR($P9="",$P9="Closed",$P9="On track"),"",IF($P9="Critical",3000,2000)+$N9+ROW()/100000) | S9: =IF($R9="","","draft Jira update for "&$A9) | T9: =IF($A9="","",HYPERLINK(JiraSite&"/browse/"&$A9,"open"))
M10: =IF($A10="","",IFERROR(INDEX(MapStage,MATCH($C10,MapStatus,0)),"Unmapped")) | N10: =IF($A10="","",AsOf-$H10) | O10: =IF(OR($M10="",$M10="Closed",$M10="Unmapped"),"",INDEX(StageStale,MATCH($M10,StageName,0))) | P10: =IF($A10="","",IF($M10="Closed","Closed",IF($J10="Y","Critical",IF(AND($I10<>"",$I10<AsOf),"Critical",IF($M10="Unmapped","Warning",IF($N10>2*$O10,"Critical",IF($N10>$O10,"Warning","On track"))))))) | Q10: =IF(OR($P10="",$P10="Closed",$P10="On track"),"",IF($J10="Y","Flagged as an impediment",IF(AND($I10<>"",$I10<AsOf),"Past due since "&TEXT($I10,"yyyy-mm-dd"),IF($M10="Unmapped","Status '"&$C10&"' is not in the Config map","No update in "&$N10&" days (limit "&$O10&")")))) | R10: =IF(OR($P10="",$P10="Closed",$P10="On track"),"",IF($P10="Critical",3000,2000)+$N10+ROW()/100000) | S10: =IF($R10="","","draft Jira update for "&$A10) | T10: =IF($A10="","",HYPERLINK(JiraSite&"/browse/"&$A10,"open"))
M11: =IF($A11="","",IFERROR(INDEX(MapStage,MATCH($C11,MapStatus,0)),"Unmapped")) | N11: =IF($A11="","",AsOf-$H11) | O11: =IF(OR($M11="",$M11="Closed",$M11="Unmapped"),"",INDEX(StageStale,MATCH($M11,StageName,0))) | P11: =IF($A11="","",IF($M11="Closed","Closed",IF($J11="Y","Critical",IF(AND($I11<>"",$I11<AsOf),"Critical",IF($M11="Unmapped","Warning",IF($N11>2*$O11,"Critical",IF($N11>$O11,"Warning","On track"))))))) | Q11: =IF(OR($P11="",$P11="Closed",$P11="On track"),"",IF($J11="Y","Flagged as an impediment",IF(AND($I11<>"",$I11<AsOf),"Past due since "&TEXT($I11,"yyyy-mm-dd"),IF($M11="Unmapped","Status '"&$C11&"' is not in the Config map","No update in "&$N11&" days (limit "&$O11&")")))) | R11: =IF(OR($P11="",$P11="Closed",$P11="On track"),"",IF($P11="Critical",3000,2000)+$N11+ROW()/100000) | S11: =IF($R11="","","draft Jira update for "&$A11) | T11: =IF($A11="","",HYPERLINK(JiraSite&"/browse/"&$A11,"open"))
M12: =IF($A12="","",IFERROR(INDEX(MapStage,MATCH($C12,MapStatus,0)),"Unmapped")) | N12: =IF($A12="","",AsOf-$H12) | O12: =IF(OR($M12="",$M12="Closed",$M12="Unmapped"),"",INDEX(StageStale,MATCH($M12,StageName,0))) | P12: =IF($A12="","",IF($M12="Closed","Closed",IF($J12="Y","Critical",IF(AND($I12<>"",$I12<AsOf),"Critical",IF($M12="Unmapped","Warning",IF($N12>2*$O12,"Critical",IF($N12>$O12,"Warning","On track"))))))) | Q12: =IF(OR($P12="",$P12="Closed",$P12="On track"),"",IF($J12="Y","Flagged as an impediment",IF(AND($I12<>"",$I12<AsOf),"Past due since "&TEXT($I12,"yyyy-mm-dd"),IF($M12="Unmapped","Status '"&$C12&"' is not in the Config map","No update in "&$N12&" days (limit "&$O12&")")))) | R12: =IF(OR($P12="",$P12="Closed",$P12="On track"),"",IF($P12="Critical",3000,2000)+$N12+ROW()/100000) | S12: =IF($R12="","","draft Jira update for "&$A12) | T12: =IF($A12="","",HYPERLINK(JiraSite&"/browse/"&$A12,"open"))
M13: =IF($A13="","",IFERROR(INDEX(MapStage,MATCH($C13,MapStatus,0)),"Unmapped")) | N13: =IF($A13="","",AsOf-$H13) | O13: =IF(OR($M13="",$M13="Closed",$M13="Unmapped"),"",INDEX(StageStale,MATCH($M13,StageName,0))) | P13: =IF($A13="","",IF($M13="Closed","Closed",IF($J13="Y","Critical",IF(AND($I13<>"",$I13<AsOf),"Critical",IF($M13="Unmapped","Warning",IF($N13>2*$O13,"Critical",IF($N13>$O13,"Warning","On track"))))))) | Q13: =IF(OR($P13="",$P13="Closed",$P13="On track"),"",IF($J13="Y","Flagged as an impediment",IF(AND($I13<>"",$I13<AsOf),"Past due since "&TEXT($I13,"yyyy-mm-dd"),IF($M13="Unmapped","Status '"&$C13&"' is not in the Config map","No update in "&$N13&" days (limit "&$O13&")")))) | R13: =IF(OR($P13="",$P13="Closed",$P13="On track"),"",IF($P13="Critical",3000,2000)+$N13+ROW()/100000) | S13: =IF($R13="","","draft Jira update for "&$A13) | T13: =IF($A13="","",HYPERLINK(JiraSite&"/browse/"&$A13,"open"))
... M501: =IF($A501="","",IFERROR(INDEX(MapStage,MATCH($C501,MapStatus,0)),"Unmapped")) | N501: =IF($A501="","",AsOf-$H501) | O501: =IF(OR($M501="",$M501="Closed",$M501="Unmapped"),"",INDEX(StageStale,MATCH($M501,StageName,0))) | P501: =IF($A501="","",IF($M501="Closed","Closed",IF($J501="Y","Critical",IF(AND($I501<>"",$I501<AsOf),"Critical",IF($M501="Unmapped","Warning",IF($N501>2*$O501,"Critical",IF($N501>$O501,"Warning","On track"))))))) | Q501: =IF(OR($P501="",$P501="Closed",$P501="On track"),"",IF($J501="Y","Flagged as an impediment",IF(AND($I501<>"",$I501<AsOf),"Past due since "&TEXT($I501,"yyyy-mm-dd"),IF($M501="Unmapped","Status '"&$C501&"' is not in the Config map","No update in "&$N501&" days (limit "&$O501&")")))) | R501: =IF(OR($P501="",$P501="Closed",$P501="On track"),"",IF($P501="Critical",3000,2000)+$N501+ROW()/100000) | S501: =IF($R501="","","draft Jira update for "&$A501) | T501: =IF($A501="","",HYPERLINK(JiraSite&"/browse/"&$A501,"open"))

Sheet Done
A1: Date | B1: Accomplishment | C1: Topic | D1: Jira | E1: Source | F1: Week of | G1: This week | H1: Rank key
F2: =IF($A2="","",$A2-WEEKDAY($A2,3)) | G2: =IF($A2="","",IF($F2=AsOf-WEEKDAY(AsOf,3),"Yes","")) | H2: =IF($G2="Yes",$A2+ROW()/100000,"")
F3: =IF($A3="","",$A3-WEEKDAY($A3,3)) | G3: =IF($A3="","",IF($F3=AsOf-WEEKDAY(AsOf,3),"Yes","")) | H3: =IF($G3="Yes",$A3+ROW()/100000,"")
F4: =IF($A4="","",$A4-WEEKDAY($A4,3)) | G4: =IF($A4="","",IF($F4=AsOf-WEEKDAY(AsOf,3),"Yes","")) | H4: =IF($G4="Yes",$A4+ROW()/100000,"")
F5: =IF($A5="","",$A5-WEEKDAY($A5,3)) | G5: =IF($A5="","",IF($F5=AsOf-WEEKDAY(AsOf,3),"Yes","")) | H5: =IF($G5="Yes",$A5+ROW()/100000,"")
F6: =IF($A6="","",$A6-WEEKDAY($A6,3)) | G6: =IF($A6="","",IF($F6=AsOf-WEEKDAY(AsOf,3),"Yes","")) | H6: =IF($G6="Yes",$A6+ROW()/100000,"")
F7: =IF($A7="","",$A7-WEEKDAY($A7,3)) | G7: =IF($A7="","",IF($F7=AsOf-WEEKDAY(AsOf,3),"Yes","")) | H7: =IF($G7="Yes",$A7+ROW()/100000,"")
F8: =IF($A8="","",$A8-WEEKDAY($A8,3)) | G8: =IF($A8="","",IF($F8=AsOf-WEEKDAY(AsOf,3),"Yes","")) | H8: =IF($G8="Yes",$A8+ROW()/100000,"")
F9: =IF($A9="","",$A9-WEEKDAY($A9,3)) | G9: =IF($A9="","",IF($F9=AsOf-WEEKDAY(AsOf,3),"Yes","")) | H9: =IF($G9="Yes",$A9+ROW()/100000,"")
F10: =IF($A10="","",$A10-WEEKDAY($A10,3)) | G10: =IF($A10="","",IF($F10=AsOf-WEEKDAY(AsOf,3),"Yes","")) | H10: =IF($G10="Yes",$A10+ROW()/100000,"")
F11: =IF($A11="","",$A11-WEEKDAY($A11,3)) | G11: =IF($A11="","",IF($F11=AsOf-WEEKDAY(AsOf,3),"Yes","")) | H11: =IF($G11="Yes",$A11+ROW()/100000,"")
F12: =IF($A12="","",$A12-WEEKDAY($A12,3)) | G12: =IF($A12="","",IF($F12=AsOf-WEEKDAY(AsOf,3),"Yes","")) | H12: =IF($G12="Yes",$A12+ROW()/100000,"")
F13: =IF($A13="","",$A13-WEEKDAY($A13,3)) | G13: =IF($A13="","",IF($F13=AsOf-WEEKDAY(AsOf,3),"Yes","")) | H13: =IF($G13="Yes",$A13+ROW()/100000,"")
... F1001: =IF($A1001="","",$A1001-WEEKDAY($A1001,3)) | G1001: =IF($A1001="","",IF($F1001=AsOf-WEEKDAY(AsOf,3),"Yes","")) | H1001: =IF($G1001="Yes",$A1001+ROW()/100000,"")

Sheet Answers
A1: ID | B1: Date | C1: Question | D1: Kind | E1: Answer or route | F1: Source | G1: Asked by | H1: Ref | I1: Times reused
I2: =IF($A2="","",COUNTIFS($H$2:$H$1001,$A2,$D$2:$D$1001,"Reuse"))
I3: =IF($A3="","",COUNTIFS($H$2:$H$1001,$A3,$D$2:$D$1001,"Reuse"))
I4: =IF($A4="","",COUNTIFS($H$2:$H$1001,$A4,$D$2:$D$1001,"Reuse"))
I5: =IF($A5="","",COUNTIFS($H$2:$H$1001,$A5,$D$2:$D$1001,"Reuse"))
I6: =IF($A6="","",COUNTIFS($H$2:$H$1001,$A6,$D$2:$D$1001,"Reuse"))
I7: =IF($A7="","",COUNTIFS($H$2:$H$1001,$A7,$D$2:$D$1001,"Reuse"))
I8: =IF($A8="","",COUNTIFS($H$2:$H$1001,$A8,$D$2:$D$1001,"Reuse"))
I9: =IF($A9="","",COUNTIFS($H$2:$H$1001,$A9,$D$2:$D$1001,"Reuse"))
I10: =IF($A10="","",COUNTIFS($H$2:$H$1001,$A10,$D$2:$D$1001,"Reuse"))
I11: =IF($A11="","",COUNTIFS($H$2:$H$1001,$A11,$D$2:$D$1001,"Reuse"))
I12: =IF($A12="","",COUNTIFS($H$2:$H$1001,$A12,$D$2:$D$1001,"Reuse"))
I13: =IF($A13="","",COUNTIFS($H$2:$H$1001,$A13,$D$2:$D$1001,"Reuse"))
... I1001: =IF($A1001="","",COUNTIFS($H$2:$H$1001,$A1001,$D$2:$D$1001,"Reuse"))

Sheet Reviews
A1: Date | B1: Artifact | C1: Author | D1: Passed | E1: Failed | F1: Verdict | G1: Top fix

Sheet Changes
A1: Date | B1: What changed | C1: From | D1: To | E1: References updated | F1: Approved by

Sheet Topics
A1: Topic | B1: Name | C1: Owner | D1: Forum | E1: Jira label | F1: Status | G1: Notes doc | H1: Open items | I1: Jira issues | J1: Jira attention
H2: =IF($A2="","",COUNTIFS(Inventory!$D:$D,$A2,Inventory!$K:$K,"Open")+COUNTIFS(Inventory!$D:$D,$A2,Inventory!$K:$K,"Unconfirmed")) | I2: =IF($A2="","",COUNTIFS(Jira!$L:$L,$A2)-COUNTIFS(Jira!$L:$L,$A2,Jira!$M:$M,"Closed")) | J2: =IF($A2="","",COUNTIFS(Jira!$L:$L,$A2,Jira!$P:$P,"Critical")+COUNTIFS(Jira!$L:$L,$A2,Jira!$P:$P,"Warning"))
H3: =IF($A3="","",COUNTIFS(Inventory!$D:$D,$A3,Inventory!$K:$K,"Open")+COUNTIFS(Inventory!$D:$D,$A3,Inventory!$K:$K,"Unconfirmed")) | I3: =IF($A3="","",COUNTIFS(Jira!$L:$L,$A3)-COUNTIFS(Jira!$L:$L,$A3,Jira!$M:$M,"Closed")) | J3: =IF($A3="","",COUNTIFS(Jira!$L:$L,$A3,Jira!$P:$P,"Critical")+COUNTIFS(Jira!$L:$L,$A3,Jira!$P:$P,"Warning"))
H4: =IF($A4="","",COUNTIFS(Inventory!$D:$D,$A4,Inventory!$K:$K,"Open")+COUNTIFS(Inventory!$D:$D,$A4,Inventory!$K:$K,"Unconfirmed")) | I4: =IF($A4="","",COUNTIFS(Jira!$L:$L,$A4)-COUNTIFS(Jira!$L:$L,$A4,Jira!$M:$M,"Closed")) | J4: =IF($A4="","",COUNTIFS(Jira!$L:$L,$A4,Jira!$P:$P,"Critical")+COUNTIFS(Jira!$L:$L,$A4,Jira!$P:$P,"Warning"))
H5: =IF($A5="","",COUNTIFS(Inventory!$D:$D,$A5,Inventory!$K:$K,"Open")+COUNTIFS(Inventory!$D:$D,$A5,Inventory!$K:$K,"Unconfirmed")) | I5: =IF($A5="","",COUNTIFS(Jira!$L:$L,$A5)-COUNTIFS(Jira!$L:$L,$A5,Jira!$M:$M,"Closed")) | J5: =IF($A5="","",COUNTIFS(Jira!$L:$L,$A5,Jira!$P:$P,"Critical")+COUNTIFS(Jira!$L:$L,$A5,Jira!$P:$P,"Warning"))
H6: =IF($A6="","",COUNTIFS(Inventory!$D:$D,$A6,Inventory!$K:$K,"Open")+COUNTIFS(Inventory!$D:$D,$A6,Inventory!$K:$K,"Unconfirmed")) | I6: =IF($A6="","",COUNTIFS(Jira!$L:$L,$A6)-COUNTIFS(Jira!$L:$L,$A6,Jira!$M:$M,"Closed")) | J6: =IF($A6="","",COUNTIFS(Jira!$L:$L,$A6,Jira!$P:$P,"Critical")+COUNTIFS(Jira!$L:$L,$A6,Jira!$P:$P,"Warning"))
H7: =IF($A7="","",COUNTIFS(Inventory!$D:$D,$A7,Inventory!$K:$K,"Open")+COUNTIFS(Inventory!$D:$D,$A7,Inventory!$K:$K,"Unconfirmed")) | I7: =IF($A7="","",COUNTIFS(Jira!$L:$L,$A7)-COUNTIFS(Jira!$L:$L,$A7,Jira!$M:$M,"Closed")) | J7: =IF($A7="","",COUNTIFS(Jira!$L:$L,$A7,Jira!$P:$P,"Critical")+COUNTIFS(Jira!$L:$L,$A7,Jira!$P:$P,"Warning"))
H8: =IF($A8="","",COUNTIFS(Inventory!$D:$D,$A8,Inventory!$K:$K,"Open")+COUNTIFS(Inventory!$D:$D,$A8,Inventory!$K:$K,"Unconfirmed")) | I8: =IF($A8="","",COUNTIFS(Jira!$L:$L,$A8)-COUNTIFS(Jira!$L:$L,$A8,Jira!$M:$M,"Closed")) | J8: =IF($A8="","",COUNTIFS(Jira!$L:$L,$A8,Jira!$P:$P,"Critical")+COUNTIFS(Jira!$L:$L,$A8,Jira!$P:$P,"Warning"))
H9: =IF($A9="","",COUNTIFS(Inventory!$D:$D,$A9,Inventory!$K:$K,"Open")+COUNTIFS(Inventory!$D:$D,$A9,Inventory!$K:$K,"Unconfirmed")) | I9: =IF($A9="","",COUNTIFS(Jira!$L:$L,$A9)-COUNTIFS(Jira!$L:$L,$A9,Jira!$M:$M,"Closed")) | J9: =IF($A9="","",COUNTIFS(Jira!$L:$L,$A9,Jira!$P:$P,"Critical")+COUNTIFS(Jira!$L:$L,$A9,Jira!$P:$P,"Warning"))
H10: =IF($A10="","",COUNTIFS(Inventory!$D:$D,$A10,Inventory!$K:$K,"Open")+COUNTIFS(Inventory!$D:$D,$A10,Inventory!$K:$K,"Unconfirmed")) | I10: =IF($A10="","",COUNTIFS(Jira!$L:$L,$A10)-COUNTIFS(Jira!$L:$L,$A10,Jira!$M:$M,"Closed")) | J10: =IF($A10="","",COUNTIFS(Jira!$L:$L,$A10,Jira!$P:$P,"Critical")+COUNTIFS(Jira!$L:$L,$A10,Jira!$P:$P,"Warning"))
H11: =IF($A11="","",COUNTIFS(Inventory!$D:$D,$A11,Inventory!$K:$K,"Open")+COUNTIFS(Inventory!$D:$D,$A11,Inventory!$K:$K,"Unconfirmed")) | I11: =IF($A11="","",COUNTIFS(Jira!$L:$L,$A11)-COUNTIFS(Jira!$L:$L,$A11,Jira!$M:$M,"Closed")) | J11: =IF($A11="","",COUNTIFS(Jira!$L:$L,$A11,Jira!$P:$P,"Critical")+COUNTIFS(Jira!$L:$L,$A11,Jira!$P:$P,"Warning"))
H12: =IF($A12="","",COUNTIFS(Inventory!$D:$D,$A12,Inventory!$K:$K,"Open")+COUNTIFS(Inventory!$D:$D,$A12,Inventory!$K:$K,"Unconfirmed")) | I12: =IF($A12="","",COUNTIFS(Jira!$L:$L,$A12)-COUNTIFS(Jira!$L:$L,$A12,Jira!$M:$M,"Closed")) | J12: =IF($A12="","",COUNTIFS(Jira!$L:$L,$A12,Jira!$P:$P,"Critical")+COUNTIFS(Jira!$L:$L,$A12,Jira!$P:$P,"Warning"))
H13: =IF($A13="","",COUNTIFS(Inventory!$D:$D,$A13,Inventory!$K:$K,"Open")+COUNTIFS(Inventory!$D:$D,$A13,Inventory!$K:$K,"Unconfirmed")) | I13: =IF($A13="","",COUNTIFS(Jira!$L:$L,$A13)-COUNTIFS(Jira!$L:$L,$A13,Jira!$M:$M,"Closed")) | J13: =IF($A13="","",COUNTIFS(Jira!$L:$L,$A13,Jira!$P:$P,"Critical")+COUNTIFS(Jira!$L:$L,$A13,Jira!$P:$P,"Warning"))
... H201: =IF($A201="","",COUNTIFS(Inventory!$D:$D,$A201,Inventory!$K:$K,"Open")+COUNTIFS(Inventory!$D:$D,$A201,Inventory!$K:$K,"Unconfirmed")) | I201: =IF($A201="","",COUNTIFS(Jira!$L:$L,$A201)-COUNTIFS(Jira!$L:$L,$A201,Jira!$M:$M,"Closed")) | J201: =IF($A201="","",COUNTIFS(Jira!$L:$L,$A201,Jira!$P:$P,"Critical")+COUNTIFS(Jira!$L:$L,$A201,Jira!$P:$P,"Warning"))

Sheet People
A1: Name | B1: Role | C1: Team | D1: Works with me on | E1: How they work | F1: Source | G1: Last updated

Sheet Commands
A1: Say this in Cowork | B1: What happens | C1: Group
A2: start my day | B2: Refresh Jira if the snapshot is stale, read the Dashboard, sweep yesterday's email, Teams and calendar, and give me the Needs You list plus anything worth logging. | C2: Daily
A3: refresh dashboard | B3: Pull Jira through the connector (or the newest CSV export), rewrite the Jira sheet, stamp the snapshot. | C3: Daily
A4: log this: <note> | B4: Capture a note into the Inventory as New, Know or Decision, with source, channel and confidence. | C4: Inventory
A5: add note to <topic>: <note> | B5: Same as log this, filed against a named topic. | C5: Inventory
A6: confirm <INV-id> | B6: Append a Confirmed row for a second-hand item. | C6: Inventory
A7: decide <INV-id>: <outcome> | B7: Close an open decision or conflict by appending a Resolved row. | C7: Inventory
A8: what's open on <topic> | B8: Open decisions, unconfirmed items, conflicts and Jira issues for one topic. | C8: Inventory
A9: done: <accomplishment> | B9: Append to the Done log under today. | C9: Reporting
A10: draft weekly report | B10: Build this week's report from the logs, email, Teams and calendar. Word draft, never sent. | C10: Reporting
A11: prep for <meeting> | B11: Agenda from open items and Jira issues for the topics that forum owns. Word draft. | C11: Reporting
A12: review this | B12: Run the Review Gate. Report what passes, what fails and the fix. Never rewrite. | C12: Quality
... A17: check integrity | B17: Scan the workbook for broken refs, duplicate IDs, unmapped statuses, and anything that looks like customer data. | C17: Upkeep

Sheet Config
A1: Config
A2: Blue cells are yours to set once. Grey cells are written by Cowork or computed. Nothing here is a secret: no tokens or passwords, ever.
A3: Settings
A4: Your name (as Jira shows it) | C4: Used to pick out issues assigned to you.
A5: Jira site URL | B5: https://YOURCOMPANY.atlassian.net | C5: No trailing slash. Builds the issue links.
A6: Jira project key(s) | B6: AIUC | C6: Comma-separated, e.g. AIUC, GENAI
A7: Jira scope in plain words | B7: All issues in the project(s) above that are not Done, plus anything closed in the last 30 days | C7: What Cowork asks the connector for. Plain English, not JQL: the Copilot connector is search, not a query engine.
A8: Sample data as-of date | C8: Leave BLANK for real use. When set, every age is measured from this date so sample data stays coherent.
A9: Today (computed) | B9: =IF(SampleAsOf="",TODAY(),SampleAsOf) -> 46300 | C9: Do not edit.
A10: Thresholds
A11: Open decision: warning after (days) | B11: 3
A12: Open decision: critical after (days) | B12: 7
A13: Unconfirmed item: warning after (days) | B13: 5
A14: Jira snapshot: stale after (days) | B14: 1
A15: Snapshot age (days) | B15: =IF(SnapshotAt="","",ROUND(IF(SampleAsOf="",NOW(),SampleAsOf+TIME(9,0,0))-SnapshotAt,1))
A16: Jira snapshot (written by Cowork on every refresh)
A17: Snapshot pulled at | C17: Written by Cowork on every Jira refresh.
A18: Snapshot source | C18: Copilot connector, or CSV export + file name.
A19: Issues in snapshot | C19: Written by Cowork. Compared to the last refresh to catch a short pull.
A21: Stages (the operating model's eight) | E21: Jira status → stage map
A22: Stage | B22: Stale after (days) | C22: Gate owner | E22: Jira status (exact) | F22: Stage
A23: Intake | B23: 7 | C23: Portfolio Lead | E23: Backlog | F23: Intake
A24: Triage | B24: 7 | C24: PM Owner | E24: To Do | F24: Intake
A25: Discovery | B25: 10 | C25: PM Owner | E25: Open | F25: Intake
A26: Design | B26: 14 | C26: Model Risk & Monitoring | E26: Intake | F26: Intake
A27: Approval | B27: 14 | C27: AI Council | E27: Triage | F27: Triage
A28: Delivery | B28: 14 | C28: Delivery Lead | E28: Discovery | F28: Discovery
A29: Scale | B29: 14 | C29: Product Owner | E29: Design | F29: Design
A30: Value | B30: 45 | C30: Finance Partner | E30: In Review | F30: Approval
E31: Governance Review | F31: Approval
E32: Approval | F32: Approval
E33: In Progress | F33: Delivery
E34: In Delivery | F34: Delivery
E35: Build | F35: Delivery
E36: Scaling | F36: Scale
E37: Rollout | F37: Scale
E38: Value Tracking | F38: Value
E39: Measuring | F39: Value
E40: Done | F40: Closed
E41: Closed | F41: Closed
...

Sheet Read Me
A1: AI Operating System
A2: What this is | B2: The system of record for your desk. Cowork appends rows to the log sheets; the Dashboard recomputes from them against today's date. Nothing on the Dashboard is typed by hand.
A3: Which cells | B3: Blue headers are inputs. Grey headers and grey cells are formulas: never type over them. Add a row by filling the first empty row's blue columns. Never insert, delete or edit rows on a log sheet: append a correction instead.
A4: Append-only | B4: Inventory, Done, Answers, Reviews and Changes are logs. A decision is closed by a new Resolved row pointing at it (Ref), a rumour by a Confirmed row. The old row stays. OneDrive version history covers the Jira sheet, the only sheet that is replaced wholesale.
A5: Privacy | B5: Nothing from 1:1s, performance or career conversations goes in this workbook. That lives in AI-OS/Private. No customer data anywhere: case or ticket IDs only.
A6: Sheets
A7: Dashboard | B7: Needs You, Jira attention, pipeline by stage, this week's accomplishments.
A8: Inventory | B8: Example row: INV-0019 | 2026-10-05 | Decision | fraud-alerts | Approve a second data engineer or slip Design a month | K. Ito | Meeting | Confirmed | | AIUC-103
A9: Jira | B9: Snapshot of the issues in scope. Rewritten by 'refresh dashboard'. Example: AIUC-103 | Fraud alert prioritization | Design | Epic | Highest | K. Ito | 2026-06-29 | 2026-09-14 | 2026-09-28 | Y | fraud | fraud-alerts
A10: Done | B10: Example row: 2026-10-05 | Got MRM sign-off on the call summarization validation plan | call-summary | AIUC-101 | Email
A11: Answers | B11: Support Guide log. Example: Q-0009 | 2026-10-05 | Who signs off a vendor model? | Routed | Routed to Third-Party Risk | Third-Party Risk team | A. Silva |
A12: Reviews | B12: One row per Review Gate run.
A13: Changes | B13: One row per file move or rename, with the references fixed.
A14: Topics | B14: One row per workstream. The slug in column A is the key every other sheet uses.
A15: People | B15: Facts about how people work. Nothing evaluative.
A16: Commands | B16: The phrases Cowork recognises.
A17: Config | B17: Jira site and project, staleness limits, the status → stage map, the snapshot stamp.
